Workbook

Sheet Summary Dashboard
A1: Meridian Pay Solutions — Third-Party Vendor Risk Assessment
A2: NIST CSF 2.0 / SIG Lite Aligned | Fictional Case Study | Assessment Period: Q1 2026
A4: Vendor | B4: Service Type | C4: Risk Tier | D4: Overall Score | E4: Risk Rating | F4: Domains Passed | G4: Domains Partial | H4: Domains Failed | I4: Assessment Date | J4: Assessor
A5: AWS | B5: Cloud Infrastructure | C5: Tier 1 – Critical | D5: =AWS!D100 -> 1 | E5: =AWS!D101 -> Low Risk | I5: 2026-01-20 | J5: GRC Analyst
A6: Payment Gateway | B6: Card Network / Tokenization | C6: Tier 1 – Critical | D6: ='Payment Gateway'!D100 -> 0.99305556 | E6: ='Payment Gateway'!D101 -> Low Risk | I6: 2026-01-20 | J6: GRC Analyst
A7: Okta | B7: Workforce Identity / SSO | C7: Tier 1 – Critical | D7: =Okta!D100 -> 1 | E7: =Okta!D101 -> Low Risk | I7: 2026-01-20 | J7: GRC Analyst
A8: KYC Vendor | B8: Identity Verification | C8: Tier 2 – High | D8: ='KYC Vendor'!D100 -> 0.75260417 | E8: ='KYC Vendor'!D101 -> Medium Risk | I8: 2026-01-20 | J8: GRC Analyst
A9: Support Contractor A | B9: Offshore Customer Support | C9: Tier 2 – High | D9: ='Support Contractor A'!D100 -> 0.30208333 | E9: ='Support Contractor A'!D101 -> Critical Risk | I9: 2026-01-20 | J9: GRC Analyst
A10: Support Contractor B | B10: Offshore Customer Support | C10: Tier 2 – High | D10: ='Support Contractor B'!D100 -> 0.24652778 | E10: ='Support Contractor B'!D101 -> Critical Risk | I10: 2026-01-20 | J10: GRC Analyst
A11: HRIS / Payroll Vendor | B11: HR & Payroll Processing | C11: Tier 2 – High | D11: ='HRIS - Payroll Vendo'!D100 -> 0.75086806 | E11: ='HRIS - Payroll Vendo'!D101 -> Medium Risk | I11: 2026-01-20 | J11: GRC Analyst

Sheet AWS
A1: Vendor Risk Assessment — AWS
A2: Service: Cloud Infrastructure | Risk Tier: Tier 1 – Critical | Meridian Pay Solutions | Q1 2026
A4: # | B4: Question | C4: Response (Y/P/N/NA) | D4: Score | E4: Notes / Evidence Required
A5: Domain 1: Organizational Security Governance
A6: 1 | B6: Does the vendor have a documented Information Security Policy reviewed at least annually? | C6: Yes | D6: =_xlfn.IFS(C6="Yes",1,C6="Partial",0.5,C6="N/A","N/A",C6="No",0) -> 1 | E6: Documentation / certification on file or available upon request.
A7: 2 | B7: Is there a dedicated security leadership role (CISO or equivalent)? | C7: Yes | D7: =_xlfn.IFS(C7="Yes",1,C7="Partial",0.5,C7="N/A","N/A",C7="No",0) -> 1 | E7: Documentation / certification on file or available upon request.
A8: 3 | B8: Does the vendor conduct annual security risk assessments? | C8: Yes | D8: =_xlfn.IFS(C8="Yes",1,C8="Partial",0.5,C8="N/A","N/A",C8="No",0) -> 1 | E8: Documentation / certification on file or available upon request.
A9: 4 | B9: Are security roles and responsibilities formally documented and communicated to staff? | C9: Yes | D9: =_xlfn.IFS(C9="Yes",1,C9="Partial",0.5,C9="N/A","N/A",C9="No",0) -> 1 | E9: Documentation / certification on file or available upon request.
A10: 5 | B10: Does the vendor maintain a security awareness training program for all employees? | C10: Yes | D10: =_xlfn.IFS(C10="Yes",1,C10="Partial",0.5,C10="N/A","N/A",C10="No",0) -> 1 | E10: Documentation / certification on file or available upon request.
A11: 6 | B11: Does the vendor have a formal third-party / supply chain risk management program? | C11: Yes | D11: =_xlfn.IFS(C11="Yes",1,C11="Partial",0.5,C11="N/A","N/A",C11="No",0) -> 1 | E11: Documentation / certification on file or available upon request.
A12: 7 | B12: Are security metrics reported regularly to executive leadership or a board? | C12: Yes | D12: =_xlfn.IFS(C12="Yes",1,C12="Partial",0.5,C12="N/A","N/A",C12="No",0) -> 1 | E12: Documentation / certification on file or available upon request.
A13: 8 | B13: Does the vendor perform background checks on employees with access to client data? | C13: Yes | D13: =_xlfn.IFS(C13="Yes",1,C13="Partial",0.5,C13="N/A","N/A",C13="No",0) -> 1 | E13: Documentation / certification on file or available upon request.
A14: 9 | B14: Does the vendor have a documented acceptable use policy for systems and data? | C14: Yes | D14: =_xlfn.IFS(C14="Yes",1,C14="Partial",0.5,C14="N/A","N/A",C14="No",0) -> 1 | E14: Documentation / certification on file or available upon request.
B15: Domain 1 Score — Organizational Security Governance | D15: =IFERROR(AVERAGEIF(D6:D14,"<>N/A",D6:D14),0) -> 1
A17: Domain 2: Data Security & Classification
A18: 10 | B18: Does the vendor maintain a data classification policy (e.g., Public, Confidential, Restricted)? | C18: Yes | D18: =_xlfn.IFS(C18="Yes",1,C18="Partial",0.5,C18="N/A","N/A",C18="No",0) -> 1 | E18: Documentation / certification on file or available upon request.
A19: 11 | B19: Is data at rest encrypted using industry-standard algorithms (AES-256 or equivalent)? | C19: Yes | D19: =_xlfn.IFS(C19="Yes",1,C19="Partial",0.5,C19="N/A","N/A",C19="No",0) -> 1 | E19: Documentation / certification on file or available upon request.
A20: 12 | B20: Is data in transit encrypted using TLS 1.2 or higher? | C20: Yes | D20: =_xlfn.IFS(C20="Yes",1,C20="Partial",0.5,C20="N/A","N/A",C20="No",0) -> 1 | E20: Documentation / certification on file or available upon request.
A21: 13 | B21: Does the vendor maintain a data inventory identifying where client data is stored and processed? | C21: Yes | D21: =_xlfn.IFS(C21="Yes",1,C21="Partial",0.5,C21="N/A","N/A",C21="No",0) -> 1 | E21: Documentation / certification on file or available upon request.
A22: 14 | B22: Are data retention and destruction policies documented and enforced? | C22: Yes | D22: =_xlfn.IFS(C22="Yes",1,C22="Partial",0.5,C22="N/A","N/A",C22="No",0) -> 1 | E22: Documentation / certification on file or available upon request.
A23: 15 | B23: Does the vendor restrict data processing to agreed geographic regions / jurisdictions? | C23: Yes | D23: =_xlfn.IFS(C23="Yes",1,C23="Partial",0.5,C23="N/A","N/A",C23="No",0) -> 1 | E23: Documentation / certification on file or available upon request.
A24: 16 | B24: Are encryption keys managed via a formal key management process (rotation, revocation)? | C24: Yes | D24: =_xlfn.IFS(C24="Yes",1,C24="Partial",0.5,C24="N/A","N/A",C24="No",0) -> 1 | E24: Documentation / certification on file or available upon request.
A25: 17 | B25: Is client data logically separated from other customers' data (multi-tenant controls)? | C25: Yes | D25: =_xlfn.IFS(C25="Yes",1,C25="Partial",0.5,C25="N/A","N/A",C25="No",0) -> 1 | E25: Documentation / certification on file or available upon request.
A26: 18 | B26: Does the vendor have controls preventing unauthorized copying or exfiltration of data? | C26: Yes | D26: =_xlfn.IFS(C26="Yes",1,C26="Partial",0.5,C26="N/A","N/A",C26="No",0) -> 1 | E26: Documentation / certification on file or available upon request.
B27: Domain 2 Score — Data Security & Classification | D27: =IFERROR(AVERAGEIF(D18:D26,"<>N/A",D18:D26),0) -> 1
A29: Domain 3: Access Control & Identity Management
A30: 19 | B30: Is multi-factor authentication (MFA) enforced for all access to systems handling client data? | C30: Yes | D30: =_xlfn.IFS(C30="Yes",1,C30="Partial",0.5,C30="N/A","N/A",C30="No",0) -> 1 | E30: Documentation / certification on file or available upon request.
A31: 20 | B31: Is role-based access control (RBAC) implemented with least-privilege principles? | C31: Yes | D31: =_xlfn.IFS(C31="Yes",1,C31="Partial",0.5,C31="N/A","N/A",C31="No",0) -> 1 | E31: Documentation / certification on file or available upon request.
A32: 21 | B32: Are privileged accounts (admin/root) managed separately with enhanced controls? | C32: Yes | D32: =_xlfn.IFS(C32="Yes",1,C32="Partial",0.5,C32="N/A","N/A",C32="No",0) -> 1 | E32: Documentation / certification on file or available upon request.
A33: 22 | B33: Are access rights reviewed and recertified at least quarterly? | C33: Yes | D33: =_xlfn.IFS(C33="Yes",1,C33="Partial",0.5,C33="N/A","N/A",C33="No",0) -> 1 | E33: Documentation / certification on file or available upon request.
A34: 23 | B34: Is access promptly revoked upon employee termination or role change? | C34: Yes | D34: =_xlfn.IFS(C34="Yes",1,C34="Partial",0.5,C34="N/A","N/A",C34="No",0) -> 1 | E34: Documentation / certification on file or available upon request.
A35: 24 | B35: Are all remote access sessions secured via VPN or equivalent encrypted tunnel? | C35: Yes | D35: =_xlfn.IFS(C35="Yes",1,C35="Partial",0.5,C35="N/A","N/A",C35="No",0) -> 1 | E35: Documentation / certification on file or available upon request.
A36: 25 | B36: Is single sign-on (SSO) implemented with a centralized identity provider? | C36: Yes | D36: =_xlfn.IFS(C36="Yes",1,C36="Partial",0.5,C36="N/A","N/A",C36="No",0) -> 1 | E36: Documentation / certification on file or available upon request.
A37: 26 | B37: Are service accounts inventoried and subject to the same access controls as user accounts? | C37: Yes | D37: =_xlfn.IFS(C37="Yes",1,C37="Partial",0.5,C37="N/A","N/A",C37="No",0) -> 1 | E37: Documentation / certification on file or available upon request.
A38: 27 | B38: Does the vendor log and monitor all privileged account activity? | C38: Yes | D38: =_xlfn.IFS(C38="Yes",1,C38="Partial",0.5,C38="N/A","N/A",C38="No",0) -> 1 | E38: Documentation / certification on file or available upon request.
B39: Domain 3 Score — Access Control & Identity Management | D39: =IFERROR(AVERAGEIF(D30:D38,"<>N/A",D30:D38),0) -> 1
A41: Domain 4: Incident Response & Notification
A42: 28 | B42: Does the vendor have a documented and tested Incident Response Plan (IRP)? | C42: Yes | D42: =_xlfn.IFS(C42="Yes",1,C42="Partial",0.5,C42="N/A","N/A",C42="No",0) -> 1 | E42: Documentation / certification on file or available upon request.
A43: 29 | B43: Are incident response roles and responsibilities (RACI) formally defined? | C43: Yes | D43: =_xlfn.IFS(C43="Yes",1,C43="Partial",0.5,C43="N/A","N/A",C43="No",0) -> 1 | E43: Documentation / certification on file or available upon request.
A44: 30 | B44: Does the vendor conduct tabletop exercises or simulated incident drills at least annually? | C44: Yes | D44: =_xlfn.IFS(C44="Yes",1,C44="Partial",0.5,C44="N/A","N/A",C44="No",0) -> 1 | E44: Documentation / certification on file or available upon request.
...

Sheet Payment Gateway
A1: Vendor Risk Assessment — Payment Gateway
A2: Service: Card Network / Tokenization | Risk Tier: Tier 1 – Critical | Meridian Pay Solutions | Q1 2026
A4: # | B4: Question | C4: Response (Y/P/N/NA) | D4: Score | E4: Notes / Evidence Required
A5: Domain 1: Organizational Security Governance
A6: 1 | B6: Does the vendor have a documented Information Security Policy reviewed at least annually? | C6: Yes | D6: =_xlfn.IFS(C6="Yes",1,C6="Partial",0.5,C6="N/A","N/A",C6="No",0) -> 1 | E6: Documentation / certification on file or available upon request.
A7: 2 | B7: Is there a dedicated security leadership role (CISO or equivalent)? | C7: Yes | D7: =_xlfn.IFS(C7="Yes",1,C7="Partial",0.5,C7="N/A","N/A",C7="No",0) -> 1 | E7: Documentation / certification on file or available upon request.
A8: 3 | B8: Does the vendor conduct annual security risk assessments? | C8: Yes | D8: =_xlfn.IFS(C8="Yes",1,C8="Partial",0.5,C8="N/A","N/A",C8="No",0) -> 1 | E8: Documentation / certification on file or available upon request.
A9: 4 | B9: Are security roles and responsibilities formally documented and communicated to staff? | C9: Yes | D9: =_xlfn.IFS(C9="Yes",1,C9="Partial",0.5,C9="N/A","N/A",C9="No",0) -> 1 | E9: Documentation / certification on file or available upon request.
A10: 5 | B10: Does the vendor maintain a security awareness training program for all employees? | C10: Yes | D10: =_xlfn.IFS(C10="Yes",1,C10="Partial",0.5,C10="N/A","N/A",C10="No",0) -> 1 | E10: Documentation / certification on file or available upon request.
A11: 6 | B11: Does the vendor have a formal third-party / supply chain risk management program? | C11: Yes | D11: =_xlfn.IFS(C11="Yes",1,C11="Partial",0.5,C11="N/A","N/A",C11="No",0) -> 1 | E11: Documentation / certification on file or available upon request.
A12: 7 | B12: Are security metrics reported regularly to executive leadership or a board? | C12: Yes | D12: =_xlfn.IFS(C12="Yes",1,C12="Partial",0.5,C12="N/A","N/A",C12="No",0) -> 1 | E12: Documentation / certification on file or available upon request.
A13: 8 | B13: Does the vendor perform background checks on employees with access to client data? | C13: Yes | D13: =_xlfn.IFS(C13="Yes",1,C13="Partial",0.5,C13="N/A","N/A",C13="No",0) -> 1 | E13: Documentation / certification on file or available upon request.
A14: 9 | B14: Does the vendor have a documented acceptable use policy for systems and data? | C14: Yes | D14: =_xlfn.IFS(C14="Yes",1,C14="Partial",0.5,C14="N/A","N/A",C14="No",0) -> 1 | E14: Documentation / certification on file or available upon request.
B15: Domain 1 Score — Organizational Security Governance | D15: =IFERROR(AVERAGEIF(D6:D14,"<>N/A",D6:D14),0) -> 1
A17: Domain 2: Data Security & Classification
A18: 10 | B18: Does the vendor maintain a data classification policy (e.g., Public, Confidential, Restricted)? | C18: Yes | D18: =_xlfn.IFS(C18="Yes",1,C18="Partial",0.5,C18="N/A","N/A",C18="No",0) -> 1 | E18: Documentation / certification on file or available upon request.
A19: 11 | B19: Is data at rest encrypted using industry-standard algorithms (AES-256 or equivalent)? | C19: Yes | D19: =_xlfn.IFS(C19="Yes",1,C19="Partial",0.5,C19="N/A","N/A",C19="No",0) -> 1 | E19: Documentation / certification on file or available upon request.
A20: 12 | B20: Is data in transit encrypted using TLS 1.2 or higher? | C20: Yes | D20: =_xlfn.IFS(C20="Yes",1,C20="Partial",0.5,C20="N/A","N/A",C20="No",0) -> 1 | E20: Documentation / certification on file or available upon request.
A21: 13 | B21: Does the vendor maintain a data inventory identifying where client data is stored and processed? | C21: Yes | D21: =_xlfn.IFS(C21="Yes",1,C21="Partial",0.5,C21="N/A","N/A",C21="No",0) -> 1 | E21: Documentation / certification on file or available upon request.
A22: 14 | B22: Are data retention and destruction policies documented and enforced? | C22: Yes | D22: =_xlfn.IFS(C22="Yes",1,C22="Partial",0.5,C22="N/A","N/A",C22="No",0) -> 1 | E22: Documentation / certification on file or available upon request.
A23: 15 | B23: Does the vendor restrict data processing to agreed geographic regions / jurisdictions? | C23: Yes | D23: =_xlfn.IFS(C23="Yes",1,C23="Partial",0.5,C23="N/A","N/A",C23="No",0) -> 1 | E23: Documentation / certification on file or available upon request.
A24: 16 | B24: Are encryption keys managed via a formal key management process (rotation, revocation)? | C24: Yes | D24: =_xlfn.IFS(C24="Yes",1,C24="Partial",0.5,C24="N/A","N/A",C24="No",0) -> 1 | E24: Documentation / certification on file or available upon request.
A25: 17 | B25: Is client data logically separated from other customers' data (multi-tenant controls)? | C25: Yes | D25: =_xlfn.IFS(C25="Yes",1,C25="Partial",0.5,C25="N/A","N/A",C25="No",0) -> 1 | E25: Documentation / certification on file or available upon request.
A26: 18 | B26: Does the vendor have controls preventing unauthorized copying or exfiltration of data? | C26: Yes | D26: =_xlfn.IFS(C26="Yes",1,C26="Partial",0.5,C26="N/A","N/A",C26="No",0) -> 1 | E26: Documentation / certification on file or available upon request.
B27: Domain 2 Score — Data Security & Classification | D27: =IFERROR(AVERAGEIF(D18:D26,"<>N/A",D18:D26),0) -> 1
A29: Domain 3: Access Control & Identity Management
A30: 19 | B30: Is multi-factor authentication (MFA) enforced for all access to systems handling client data? | C30: Yes | D30: =_xlfn.IFS(C30="Yes",1,C30="Partial",0.5,C30="N/A","N/A",C30="No",0) -> 1 | E30: Documentation / certification on file or available upon request.
A31: 20 | B31: Is role-based access control (RBAC) implemented with least-privilege principles? | C31: Yes | D31: =_xlfn.IFS(C31="Yes",1,C31="Partial",0.5,C31="N/A","N/A",C31="No",0) -> 1 | E31: Documentation / certification on file or available upon request.
A32: 21 | B32: Are privileged accounts (admin/root) managed separately with enhanced controls? | C32: Yes | D32: =_xlfn.IFS(C32="Yes",1,C32="Partial",0.5,C32="N/A","N/A",C32="No",0) -> 1 | E32: Documentation / certification on file or available upon request.
A33: 22 | B33: Are access rights reviewed and recertified at least quarterly? | C33: Yes | D33: =_xlfn.IFS(C33="Yes",1,C33="Partial",0.5,C33="N/A","N/A",C33="No",0) -> 1 | E33: Documentation / certification on file or available upon request.
A34: 23 | B34: Is access promptly revoked upon employee termination or role change? | C34: Yes | D34: =_xlfn.IFS(C34="Yes",1,C34="Partial",0.5,C34="N/A","N/A",C34="No",0) -> 1 | E34: Documentation / certification on file or available upon request.
A35: 24 | B35: Are all remote access sessions secured via VPN or equivalent encrypted tunnel? | C35: Yes | D35: =_xlfn.IFS(C35="Yes",1,C35="Partial",0.5,C35="N/A","N/A",C35="No",0) -> 1 | E35: Documentation / certification on file or available upon request.
A36: 25 | B36: Is single sign-on (SSO) implemented with a centralized identity provider? | C36: Yes | D36: =_xlfn.IFS(C36="Yes",1,C36="Partial",0.5,C36="N/A","N/A",C36="No",0) -> 1 | E36: Documentation / certification on file or available upon request.
A37: 26 | B37: Are service accounts inventoried and subject to the same access controls as user accounts? | C37: Yes | D37: =_xlfn.IFS(C37="Yes",1,C37="Partial",0.5,C37="N/A","N/A",C37="No",0) -> 1 | E37: Documentation / certification on file or available upon request.
A38: 27 | B38: Does the vendor log and monitor all privileged account activity? | C38: Yes | D38: =_xlfn.IFS(C38="Yes",1,C38="Partial",0.5,C38="N/A","N/A",C38="No",0) -> 1 | E38: Documentation / certification on file or available upon request.
B39: Domain 3 Score — Access Control & Identity Management | D39: =IFERROR(AVERAGEIF(D30:D38,"<>N/A",D30:D38),0) -> 1
A41: Domain 4: Incident Response & Notification
A42: 28 | B42: Does the vendor have a documented and tested Incident Response Plan (IRP)? | C42: Yes | D42: =_xlfn.IFS(C42="Yes",1,C42="Partial",0.5,C42="N/A","N/A",C42="No",0) -> 1 | E42: Documentation / certification on file or available upon request.
A43: 29 | B43: Are incident response roles and responsibilities (RACI) formally defined? | C43: Yes | D43: =_xlfn.IFS(C43="Yes",1,C43="Partial",0.5,C43="N/A","N/A",C43="No",0) -> 1 | E43: Documentation / certification on file or available upon request.
A44: 30 | B44: Does the vendor conduct tabletop exercises or simulated incident drills at least annually? | C44: Yes | D44: =_xlfn.IFS(C44="Yes",1,C44="Partial",0.5,C44="N/A","N/A",C44="No",0) -> 1 | E44: Documentation / certification on file or available upon request.
...

Sheet Okta
A1: Vendor Risk Assessment — Okta
A2: Service: Workforce Identity / SSO | Risk Tier: Tier 1 – Critical | Meridian Pay Solutions | Q1 2026
A4: # | B4: Question | C4: Response (Y/P/N/NA) | D4: Score | E4: Notes / Evidence Required
A5: Domain 1: Organizational Security Governance
A6: 1 | B6: Does the vendor have a documented Information Security Policy reviewed at least annually? | C6: Yes | D6: =_xlfn.IFS(C6="Yes",1,C6="Partial",0.5,C6="N/A","N/A",C6="No",0) -> 1 | E6: Documentation / certification on file or available upon request.
A7: 2 | B7: Is there a dedicated security leadership role (CISO or equivalent)? | C7: Yes | D7: =_xlfn.IFS(C7="Yes",1,C7="Partial",0.5,C7="N/A","N/A",C7="No",0) -> 1 | E7: Documentation / certification on file or available upon request.
A8: 3 | B8: Does the vendor conduct annual security risk assessments? | C8: Yes | D8: =_xlfn.IFS(C8="Yes",1,C8="Partial",0.5,C8="N/A","N/A",C8="No",0) -> 1 | E8: Documentation / certification on file or available upon request.
A9: 4 | B9: Are security roles and responsibilities formally documented and communicated to staff? | C9: Yes | D9: =_xlfn.IFS(C9="Yes",1,C9="Partial",0.5,C9="N/A","N/A",C9="No",0) -> 1 | E9: Documentation / certification on file or available upon request.
A10: 5 | B10: Does the vendor maintain a security awareness training program for all employees? | C10: Yes | D10: =_xlfn.IFS(C10="Yes",1,C10="Partial",0.5,C10="N/A","N/A",C10="No",0) -> 1 | E10: Documentation / certification on file or available upon request.
A11: 6 | B11: Does the vendor have a formal third-party / supply chain risk management program? | C11: Yes | D11: =_xlfn.IFS(C11="Yes",1,C11="Partial",0.5,C11="N/A","N/A",C11="No",0) -> 1 | E11: Documentation / certification on file or available upon request.
A12: 7 | B12: Are security metrics reported regularly to executive leadership or a board? | C12: Yes | D12: =_xlfn.IFS(C12="Yes",1,C12="Partial",0.5,C12="N/A","N/A",C12="No",0) -> 1 | E12: Documentation / certification on file or available upon request.
A13: 8 | B13: Does the vendor perform background checks on employees with access to client data? | C13: Yes | D13: =_xlfn.IFS(C13="Yes",1,C13="Partial",0.5,C13="N/A","N/A",C13="No",0) -> 1 | E13: Documentation / certification on file or available upon request.
A14: 9 | B14: Does the vendor have a documented acceptable use policy for systems and data? | C14: Yes | D14: =_xlfn.IFS(C14="Yes",1,C14="Partial",0.5,C14="N/A","N/A",C14="No",0) -> 1 | E14: Documentation / certification on file or available upon request.
B15: Domain 1 Score — Organizational Security Governance | D15: =IFERROR(AVERAGEIF(D6:D14,"<>N/A",D6:D14),0) -> 1
A17: Domain 2: Data Security & Classification
A18: 10 | B18: Does the vendor maintain a data classification policy (e.g., Public, Confidential, Restricted)? | C18: Yes | D18: =_xlfn.IFS(C18="Yes",1,C18="Partial",0.5,C18="N/A","N/A",C18="No",0) -> 1 | E18: Documentation / certification on file or available upon request.
A19: 11 | B19: Is data at rest encrypted using industry-standard algorithms (AES-256 or equivalent)? | C19: Yes | D19: =_xlfn.IFS(C19="Yes",1,C19="Partial",0.5,C19="N/A","N/A",C19="No",0) -> 1 | E19: Documentation / certification on file or available upon request.
A20: 12 | B20: Is data in transit encrypted using TLS 1.2 or higher? | C20: Yes | D20: =_xlfn.IFS(C20="Yes",1,C20="Partial",0.5,C20="N/A","N/A",C20="No",0) -> 1 | E20: Documentation / certification on file or available upon request.
A21: 13 | B21: Does the vendor maintain a data inventory identifying where client data is stored and processed? | C21: Yes | D21: =_xlfn.IFS(C21="Yes",1,C21="Partial",0.5,C21="N/A","N/A",C21="No",0) -> 1 | E21: Documentation / certification on file or available upon request.
A22: 14 | B22: Are data retention and destruction policies documented and enforced? | C22: Yes | D22: =_xlfn.IFS(C22="Yes",1,C22="Partial",0.5,C22="N/A","N/A",C22="No",0) -> 1 | E22: Documentation / certification on file or available upon request.
A23: 15 | B23: Does the vendor restrict data processing to agreed geographic regions / jurisdictions? | C23: Yes | D23: =_xlfn.IFS(C23="Yes",1,C23="Partial",0.5,C23="N/A","N/A",C23="No",0) -> 1 | E23: Documentation / certification on file or available upon request.
A24: 16 | B24: Are encryption keys managed via a formal key management process (rotation, revocation)? | C24: Yes | D24: =_xlfn.IFS(C24="Yes",1,C24="Partial",0.5,C24="N/A","N/A",C24="No",0) -> 1 | E24: Documentation / certification on file or available upon request.
A25: 17 | B25: Is client data logically separated from other customers' data (multi-tenant controls)? | C25: Yes | D25: =_xlfn.IFS(C25="Yes",1,C25="Partial",0.5,C25="N/A","N/A",C25="No",0) -> 1 | E25: Documentation / certification on file or available upon request.
A26: 18 | B26: Does the vendor have controls preventing unauthorized copying or exfiltration of data? | C26: Yes | D26: =_xlfn.IFS(C26="Yes",1,C26="Partial",0.5,C26="N/A","N/A",C26="No",0) -> 1 | E26: Documentation / certification on file or available upon request.
B27: Domain 2 Score — Data Security & Classification | D27: =IFERROR(AVERAGEIF(D18:D26,"<>N/A",D18:D26),0) -> 1
A29: Domain 3: Access Control & Identity Management
A30: 19 | B30: Is multi-factor authentication (MFA) enforced for all access to systems handling client data? | C30: Yes | D30: =_xlfn.IFS(C30="Yes",1,C30="Partial",0.5,C30="N/A","N/A",C30="No",0) -> 1 | E30: Documentation / certification on file or available upon request.
A31: 20 | B31: Is role-based access control (RBAC) implemented with least-privilege principles? | C31: Yes | D31: =_xlfn.IFS(C31="Yes",1,C31="Partial",0.5,C31="N/A","N/A",C31="No",0) -> 1 | E31: Documentation / certification on file or available upon request.
A32: 21 | B32: Are privileged accounts (admin/root) managed separately with enhanced controls? | C32: Yes | D32: =_xlfn.IFS(C32="Yes",1,C32="Partial",0.5,C32="N/A","N/A",C32="No",0) -> 1 | E32: Documentation / certification on file or available upon request.
A33: 22 | B33: Are access rights reviewed and recertified at least quarterly? | C33: Yes | D33: =_xlfn.IFS(C33="Yes",1,C33="Partial",0.5,C33="N/A","N/A",C33="No",0) -> 1 | E33: Documentation / certification on file or available upon request.
A34: 23 | B34: Is access promptly revoked upon employee termination or role change? | C34: Yes | D34: =_xlfn.IFS(C34="Yes",1,C34="Partial",0.5,C34="N/A","N/A",C34="No",0) -> 1 | E34: Documentation / certification on file or available upon request.
A35: 24 | B35: Are all remote access sessions secured via VPN or equivalent encrypted tunnel? | C35: Yes | D35: =_xlfn.IFS(C35="Yes",1,C35="Partial",0.5,C35="N/A","N/A",C35="No",0) -> 1 | E35: Documentation / certification on file or available upon request.
A36: 25 | B36: Is single sign-on (SSO) implemented with a centralized identity provider? | C36: Yes | D36: =_xlfn.IFS(C36="Yes",1,C36="Partial",0.5,C36="N/A","N/A",C36="No",0) -> 1 | E36: Documentation / certification on file or available upon request.
A37: 26 | B37: Are service accounts inventoried and subject to the same access controls as user accounts? | C37: Yes | D37: =_xlfn.IFS(C37="Yes",1,C37="Partial",0.5,C37="N/A","N/A",C37="No",0) -> 1 | E37: Documentation / certification on file or available upon request.
A38: 27 | B38: Does the vendor log and monitor all privileged account activity? | C38: Yes | D38: =_xlfn.IFS(C38="Yes",1,C38="Partial",0.5,C38="N/A","N/A",C38="No",0) -> 1 | E38: Documentation / certification on file or available upon request.
B39: Domain 3 Score — Access Control & Identity Management | D39: =IFERROR(AVERAGEIF(D30:D38,"<>N/A",D30:D38),0) -> 1
A41: Domain 4: Incident Response & Notification
A42: 28 | B42: Does the vendor have a documented and tested Incident Response Plan (IRP)? | C42: Yes | D42: =_xlfn.IFS(C42="Yes",1,C42="Partial",0.5,C42="N/A","N/A",C42="No",0) -> 1 | E42: Documentation / certification on file or available upon request.
A43: 29 | B43: Are incident response roles and responsibilities (RACI) formally defined? | C43: Yes | D43: =_xlfn.IFS(C43="Yes",1,C43="Partial",0.5,C43="N/A","N/A",C43="No",0) -> 1 | E43: Documentation / certification on file or available upon request.
A44: 30 | B44: Does the vendor conduct tabletop exercises or simulated incident drills at least annually? | C44: Yes | D44: =_xlfn.IFS(C44="Yes",1,C44="Partial",0.5,C44="N/A","N/A",C44="No",0) -> 1 | E44: Documentation / certification on file or available upon request.
...

Sheet KYC Vendor
A1: Vendor Risk Assessment — KYC Vendor
A2: Service: Identity Verification | Risk Tier: Tier 2 – High | Meridian Pay Solutions | Q1 2026
A4: # | B4: Question | C4: Response (Y/P/N/NA) | D4: Score | E4: Notes / Evidence Required
A5: Domain 1: Organizational Security Governance
A6: 1 | B6: Does the vendor have a documented Information Security Policy reviewed at least annually? | C6: Yes | D6: =_xlfn.IFS(C6="Yes",1,C6="Partial",0.5,C6="N/A","N/A",C6="No",0) -> 1 | E6: Documentation / certification on file or available upon request.
A7: 2 | B7: Is there a dedicated security leadership role (CISO or equivalent)? | C7: Partial | D7: =_xlfn.IFS(C7="Yes",1,C7="Partial",0.5,C7="N/A","N/A",C7="No",0) -> 0.5 | E7: Partial controls in place — gap remediation plan or timeline requested.
A8: 3 | B8: Does the vendor conduct annual security risk assessments? | C8: Yes | D8: =_xlfn.IFS(C8="Yes",1,C8="Partial",0.5,C8="N/A","N/A",C8="No",0) -> 1 | E8: Documentation / certification on file or available upon request.
A9: 4 | B9: Are security roles and responsibilities formally documented and communicated to staff? | C9: Yes | D9: =_xlfn.IFS(C9="Yes",1,C9="Partial",0.5,C9="N/A","N/A",C9="No",0) -> 1 | E9: Documentation / certification on file or available upon request.
A10: 5 | B10: Does the vendor maintain a security awareness training program for all employees? | C10: Yes | D10: =_xlfn.IFS(C10="Yes",1,C10="Partial",0.5,C10="N/A","N/A",C10="No",0) -> 1 | E10: Documentation / certification on file or available upon request.
A11: 6 | B11: Does the vendor have a formal third-party / supply chain risk management program? | C11: Partial | D11: =_xlfn.IFS(C11="Yes",1,C11="Partial",0.5,C11="N/A","N/A",C11="No",0) -> 0.5 | E11: Partial controls in place — gap remediation plan or timeline requested.
A12: 7 | B12: Are security metrics reported regularly to executive leadership or a board? | C12: Partial | D12: =_xlfn.IFS(C12="Yes",1,C12="Partial",0.5,C12="N/A","N/A",C12="No",0) -> 0.5 | E12: Partial controls in place — gap remediation plan or timeline requested.
A13: 8 | B13: Does the vendor perform background checks on employees with access to client data? | C13: Yes | D13: =_xlfn.IFS(C13="Yes",1,C13="Partial",0.5,C13="N/A","N/A",C13="No",0) -> 1 | E13: Documentation / certification on file or available upon request.
A14: 9 | B14: Does the vendor have a documented acceptable use policy for systems and data? | C14: Yes | D14: =_xlfn.IFS(C14="Yes",1,C14="Partial",0.5,C14="N/A","N/A",C14="No",0) -> 1 | E14: Documentation / certification on file or available upon request.
B15: Domain 1 Score — Organizational Security Governance | D15: =IFERROR(AVERAGEIF(D6:D14,"<>N/A",D6:D14),0) -> 0.83333333
A17: Domain 2: Data Security & Classification
A18: 10 | B18: Does the vendor maintain a data classification policy (e.g., Public, Confidential, Restricted)? | C18: Yes | D18: =_xlfn.IFS(C18="Yes",1,C18="Partial",0.5,C18="N/A","N/A",C18="No",0) -> 1 | E18: Documentation / certification on file or available upon request.
A19: 11 | B19: Is data at rest encrypted using industry-standard algorithms (AES-256 or equivalent)? | C19: Yes | D19: =_xlfn.IFS(C19="Yes",1,C19="Partial",0.5,C19="N/A","N/A",C19="No",0) -> 1 | E19: Documentation / certification on file or available upon request.
A20: 12 | B20: Is data in transit encrypted using TLS 1.2 or higher? | C20: Yes | D20: =_xlfn.IFS(C20="Yes",1,C20="Partial",0.5,C20="N/A","N/A",C20="No",0) -> 1 | E20: Documentation / certification on file or available upon request.
A21: 13 | B21: Does the vendor maintain a data inventory identifying where client data is stored and processed? | C21: Partial | D21: =_xlfn.IFS(C21="Yes",1,C21="Partial",0.5,C21="N/A","N/A",C21="No",0) -> 0.5 | E21: Partial controls in place — gap remediation plan or timeline requested.
A22: 14 | B22: Are data retention and destruction policies documented and enforced? | C22: Yes | D22: =_xlfn.IFS(C22="Yes",1,C22="Partial",0.5,C22="N/A","N/A",C22="No",0) -> 1 | E22: Documentation / certification on file or available upon request.
A23: 15 | B23: Does the vendor restrict data processing to agreed geographic regions / jurisdictions? | C23: Yes | D23: =_xlfn.IFS(C23="Yes",1,C23="Partial",0.5,C23="N/A","N/A",C23="No",0) -> 1 | E23: Documentation / certification on file or available upon request.
A24: 16 | B24: Are encryption keys managed via a formal key management process (rotation, revocation)? | C24: Partial | D24: =_xlfn.IFS(C24="Yes",1,C24="Partial",0.5,C24="N/A","N/A",C24="No",0) -> 0.5 | E24: Partial controls in place — gap remediation plan or timeline requested.
A25: 17 | B25: Is client data logically separated from other customers' data (multi-tenant controls)? | C25: Yes | D25: =_xlfn.IFS(C25="Yes",1,C25="Partial",0.5,C25="N/A","N/A",C25="No",0) -> 1 | E25: Documentation / certification on file or available upon request.
A26: 18 | B26: Does the vendor have controls preventing unauthorized copying or exfiltration of data? | C26: Partial | D26: =_xlfn.IFS(C26="Yes",1,C26="Partial",0.5,C26="N/A","N/A",C26="No",0) -> 0.5 | E26: Partial controls in place — gap remediation plan or timeline requested.
B27: Domain 2 Score — Data Security & Classification | D27: =IFERROR(AVERAGEIF(D18:D26,"<>N/A",D18:D26),0) -> 0.83333333
A29: Domain 3: Access Control & Identity Management
A30: 19 | B30: Is multi-factor authentication (MFA) enforced for all access to systems handling client data? | C30: Yes | D30: =_xlfn.IFS(C30="Yes",1,C30="Partial",0.5,C30="N/A","N/A",C30="No",0) -> 1 | E30: Documentation / certification on file or available upon request.
A31: 20 | B31: Is role-based access control (RBAC) implemented with least-privilege principles? | C31: Yes | D31: =_xlfn.IFS(C31="Yes",1,C31="Partial",0.5,C31="N/A","N/A",C31="No",0) -> 1 | E31: Documentation / certification on file or available upon request.
A32: 21 | B32: Are privileged accounts (admin/root) managed separately with enhanced controls? | C32: Yes | D32: =_xlfn.IFS(C32="Yes",1,C32="Partial",0.5,C32="N/A","N/A",C32="No",0) -> 1 | E32: Documentation / certification on file or available upon request.
A33: 22 | B33: Are access rights reviewed and recertified at least quarterly? | C33: Partial | D33: =_xlfn.IFS(C33="Yes",1,C33="Partial",0.5,C33="N/A","N/A",C33="No",0) -> 0.5 | E33: Partial controls in place — gap remediation plan or timeline requested.
A34: 23 | B34: Is access promptly revoked upon employee termination or role change? | C34: Yes | D34: =_xlfn.IFS(C34="Yes",1,C34="Partial",0.5,C34="N/A","N/A",C34="No",0) -> 1 | E34: Documentation / certification on file or available upon request.
A35: 24 | B35: Are all remote access sessions secured via VPN or equivalent encrypted tunnel? | C35: Yes | D35: =_xlfn.IFS(C35="Yes",1,C35="Partial",0.5,C35="N/A","N/A",C35="No",0) -> 1 | E35: Documentation / certification on file or available upon request.
A36: 25 | B36: Is single sign-on (SSO) implemented with a centralized identity provider? | C36: Partial | D36: =_xlfn.IFS(C36="Yes",1,C36="Partial",0.5,C36="N/A","N/A",C36="No",0) -> 0.5 | E36: Partial controls in place — gap remediation plan or timeline requested.
A37: 26 | B37: Are service accounts inventoried and subject to the same access controls as user accounts? | C37: Partial | D37: =_xlfn.IFS(C37="Yes",1,C37="Partial",0.5,C37="N/A","N/A",C37="No",0) -> 0.5 | E37: Partial controls in place — gap remediation plan or timeline requested.
A38: 27 | B38: Does the vendor log and monitor all privileged account activity? | C38: Partial | D38: =_xlfn.IFS(C38="Yes",1,C38="Partial",0.5,C38="N/A","N/A",C38="No",0) -> 0.5 | E38: Partial controls in place — gap remediation plan or timeline requested.
B39: Domain 3 Score — Access Control & Identity Management | D39: =IFERROR(AVERAGEIF(D30:D38,"<>N/A",D30:D38),0) -> 0.77777778
A41: Domain 4: Incident Response & Notification
A42: 28 | B42: Does the vendor have a documented and tested Incident Response Plan (IRP)? | C42: Yes | D42: =_xlfn.IFS(C42="Yes",1,C42="Partial",0.5,C42="N/A","N/A",C42="No",0) -> 1 | E42: Documentation / certification on file or available upon request.
A43: 29 | B43: Are incident response roles and responsibilities (RACI) formally defined? | C43: Yes | D43: =_xlfn.IFS(C43="Yes",1,C43="Partial",0.5,C43="N/A","N/A",C43="No",0) -> 1 | E43: Documentation / certification on file or available upon request.
A44: 30 | B44: Does the vendor conduct tabletop exercises or simulated incident drills at least annually? | C44: Partial | D44: =_xlfn.IFS(C44="Yes",1,C44="Partial",0.5,C44="N/A","N/A",C44="No",0) -> 0.5 | E44: Partial controls in place — gap remediation plan or timeline requested.
...

Sheet Support Contractor A
A1: Vendor Risk Assessment — Support Contractor A
A2: Service: Offshore Customer Support | Risk Tier: Tier 2 – High | Meridian Pay Solutions | Q1 2026
A4: # | B4: Question | C4: Response (Y/P/N/NA) | D4: Score | E4: Notes / Evidence Required
A5: Domain 1: Organizational Security Governance
A6: 1 | B6: Does the vendor have a documented Information Security Policy reviewed at least annually? | C6: Partial | D6: =_xlfn.IFS(C6="Yes",1,C6="Partial",0.5,C6="N/A","N/A",C6="No",0) -> 0.5 | E6: Partial controls in place — gap remediation plan or timeline requested.
A7: 2 | B7: Is there a dedicated security leadership role (CISO or equivalent)? | C7: No | D7: =_xlfn.IFS(C7="Yes",1,C7="Partial",0.5,C7="N/A","N/A",C7="No",0) -> 0 | E7: Control not in place — vendor must provide remediation timeline.
A8: 3 | B8: Does the vendor conduct annual security risk assessments? | C8: Partial | D8: =_xlfn.IFS(C8="Yes",1,C8="Partial",0.5,C8="N/A","N/A",C8="No",0) -> 0.5 | E8: Partial controls in place — gap remediation plan or timeline requested.
A9: 4 | B9: Are security roles and responsibilities formally documented and communicated to staff? | C9: Partial | D9: =_xlfn.IFS(C9="Yes",1,C9="Partial",0.5,C9="N/A","N/A",C9="No",0) -> 0.5 | E9: Partial controls in place — gap remediation plan or timeline requested.
A10: 5 | B10: Does the vendor maintain a security awareness training program for all employees? | C10: Partial | D10: =_xlfn.IFS(C10="Yes",1,C10="Partial",0.5,C10="N/A","N/A",C10="No",0) -> 0.5 | E10: Partial controls in place — gap remediation plan or timeline requested.
A11: 6 | B11: Does the vendor have a formal third-party / supply chain risk management program? | C11: No | D11: =_xlfn.IFS(C11="Yes",1,C11="Partial",0.5,C11="N/A","N/A",C11="No",0) -> 0 | E11: Control not in place — vendor must provide remediation timeline.
A12: 7 | B12: Are security metrics reported regularly to executive leadership or a board? | C12: No | D12: =_xlfn.IFS(C12="Yes",1,C12="Partial",0.5,C12="N/A","N/A",C12="No",0) -> 0 | E12: Control not in place — vendor must provide remediation timeline.
A13: 8 | B13: Does the vendor perform background checks on employees with access to client data? | C13: Yes | D13: =_xlfn.IFS(C13="Yes",1,C13="Partial",0.5,C13="N/A","N/A",C13="No",0) -> 1 | E13: Documentation / certification on file or available upon request.
A14: 9 | B14: Does the vendor have a documented acceptable use policy for systems and data? | C14: Partial | D14: =_xlfn.IFS(C14="Yes",1,C14="Partial",0.5,C14="N/A","N/A",C14="No",0) -> 0.5 | E14: Partial controls in place — gap remediation plan or timeline requested.
B15: Domain 1 Score — Organizational Security Governance | D15: =IFERROR(AVERAGEIF(D6:D14,"<>N/A",D6:D14),0) -> 0.38888889
A17: Domain 2: Data Security & Classification
A18: 10 | B18: Does the vendor maintain a data classification policy (e.g., Public, Confidential, Restricted)? | C18: Partial | D18: =_xlfn.IFS(C18="Yes",1,C18="Partial",0.5,C18="N/A","N/A",C18="No",0) -> 0.5 | E18: Partial controls in place — gap remediation plan or timeline requested.
A19: 11 | B19: Is data at rest encrypted using industry-standard algorithms (AES-256 or equivalent)? | C19: Yes | D19: =_xlfn.IFS(C19="Yes",1,C19="Partial",0.5,C19="N/A","N/A",C19="No",0) -> 1 | E19: Documentation / certification on file or available upon request.
A20: 12 | B20: Is data in transit encrypted using TLS 1.2 or higher? | C20: Yes | D20: =_xlfn.IFS(C20="Yes",1,C20="Partial",0.5,C20="N/A","N/A",C20="No",0) -> 1 | E20: Documentation / certification on file or available upon request.
A21: 13 | B21: Does the vendor maintain a data inventory identifying where client data is stored and processed? | C21: No | D21: =_xlfn.IFS(C21="Yes",1,C21="Partial",0.5,C21="N/A","N/A",C21="No",0) -> 0 | E21: Control not in place — vendor must provide remediation timeline.
A22: 14 | B22: Are data retention and destruction policies documented and enforced? | C22: Partial | D22: =_xlfn.IFS(C22="Yes",1,C22="Partial",0.5,C22="N/A","N/A",C22="No",0) -> 0.5 | E22: Partial controls in place — gap remediation plan or timeline requested.
A23: 15 | B23: Does the vendor restrict data processing to agreed geographic regions / jurisdictions? | C23: No | D23: =_xlfn.IFS(C23="Yes",1,C23="Partial",0.5,C23="N/A","N/A",C23="No",0) -> 0 | E23: Control not in place — vendor must provide remediation timeline.
A24: 16 | B24: Are encryption keys managed via a formal key management process (rotation, revocation)? | C24: No | D24: =_xlfn.IFS(C24="Yes",1,C24="Partial",0.5,C24="N/A","N/A",C24="No",0) -> 0 | E24: Control not in place — vendor must provide remediation timeline.
A25: 17 | B25: Is client data logically separated from other customers' data (multi-tenant controls)? | C25: Partial | D25: =_xlfn.IFS(C25="Yes",1,C25="Partial",0.5,C25="N/A","N/A",C25="No",0) -> 0.5 | E25: Partial controls in place — gap remediation plan or timeline requested.
A26: 18 | B26: Does the vendor have controls preventing unauthorized copying or exfiltration of data? | C26: Partial | D26: =_xlfn.IFS(C26="Yes",1,C26="Partial",0.5,C26="N/A","N/A",C26="No",0) -> 0.5 | E26: Partial controls in place — gap remediation plan or timeline requested.
B27: Domain 2 Score — Data Security & Classification | D27: =IFERROR(AVERAGEIF(D18:D26,"<>N/A",D18:D26),0) -> 0.44444444
A29: Domain 3: Access Control & Identity Management
A30: 19 | B30: Is multi-factor authentication (MFA) enforced for all access to systems handling client data? | C30: Partial | D30: =_xlfn.IFS(C30="Yes",1,C30="Partial",0.5,C30="N/A","N/A",C30="No",0) -> 0.5 | E30: Partial controls in place — gap remediation plan or timeline requested.
A31: 20 | B31: Is role-based access control (RBAC) implemented with least-privilege principles? | C31: Partial | D31: =_xlfn.IFS(C31="Yes",1,C31="Partial",0.5,C31="N/A","N/A",C31="No",0) -> 0.5 | E31: Partial controls in place — gap remediation plan or timeline requested.
A32: 21 | B32: Are privileged accounts (admin/root) managed separately with enhanced controls? | C32: Partial | D32: =_xlfn.IFS(C32="Yes",1,C32="Partial",0.5,C32="N/A","N/A",C32="No",0) -> 0.5 | E32: Partial controls in place — gap remediation plan or timeline requested.
A33: 22 | B33: Are access rights reviewed and recertified at least quarterly? | C33: No | D33: =_xlfn.IFS(C33="Yes",1,C33="Partial",0.5,C33="N/A","N/A",C33="No",0) -> 0 | E33: Control not in place — vendor must provide remediation timeline.
A34: 23 | B34: Is access promptly revoked upon employee termination or role change? | C34: Partial | D34: =_xlfn.IFS(C34="Yes",1,C34="Partial",0.5,C34="N/A","N/A",C34="No",0) -> 0.5 | E34: Partial controls in place — gap remediation plan or timeline requested.
A35: 24 | B35: Are all remote access sessions secured via VPN or equivalent encrypted tunnel? | C35: Yes | D35: =_xlfn.IFS(C35="Yes",1,C35="Partial",0.5,C35="N/A","N/A",C35="No",0) -> 1 | E35: Documentation / certification on file or available upon request.
A36: 25 | B36: Is single sign-on (SSO) implemented with a centralized identity provider? | C36: No | D36: =_xlfn.IFS(C36="Yes",1,C36="Partial",0.5,C36="N/A","N/A",C36="No",0) -> 0 | E36: Control not in place — vendor must provide remediation timeline.
A37: 26 | B37: Are service accounts inventoried and subject to the same access controls as user accounts? | C37: No | D37: =_xlfn.IFS(C37="Yes",1,C37="Partial",0.5,C37="N/A","N/A",C37="No",0) -> 0 | E37: Control not in place — vendor must provide remediation timeline.
A38: 27 | B38: Does the vendor log and monitor all privileged account activity? | C38: Partial | D38: =_xlfn.IFS(C38="Yes",1,C38="Partial",0.5,C38="N/A","N/A",C38="No",0) -> 0.5 | E38: Partial controls in place — gap remediation plan or timeline requested.
B39: Domain 3 Score — Access Control & Identity Management | D39: =IFERROR(AVERAGEIF(D30:D38,"<>N/A",D30:D38),0) -> 0.38888889
A41: Domain 4: Incident Response & Notification
A42: 28 | B42: Does the vendor have a documented and tested Incident Response Plan (IRP)? | C42: Partial | D42: =_xlfn.IFS(C42="Yes",1,C42="Partial",0.5,C42="N/A","N/A",C42="No",0) -> 0.5 | E42: Partial controls in place — gap remediation plan or timeline requested.
A43: 29 | B43: Are incident response roles and responsibilities (RACI) formally defined? | C43: Partial | D43: =_xlfn.IFS(C43="Yes",1,C43="Partial",0.5,C43="N/A","N/A",C43="No",0) -> 0.5 | E43: Partial controls in place — gap remediation plan or timeline requested.
A44: 30 | B44: Does the vendor conduct tabletop exercises or simulated incident drills at least annually? | C44: No | D44: =_xlfn.IFS(C44="Yes",1,C44="Partial",0.5,C44="N/A","N/A",C44="No",0) -> 0 | E44: Control not in place — vendor must provide remediation timeline.
...

Sheet Support Contractor B
A1: Vendor Risk Assessment — Support Contractor B
A2: Service: Offshore Customer Support | Risk Tier: Tier 2 – High | Meridian Pay Solutions | Q1 2026
A4: # | B4: Question | C4: Response (Y/P/N/NA) | D4: Score | E4: Notes / Evidence Required
A5: Domain 1: Organizational Security Governance
A6: 1 | B6: Does the vendor have a documented Information Security Policy reviewed at least annually? | C6: Partial | D6: =_xlfn.IFS(C6="Yes",1,C6="Partial",0.5,C6="N/A","N/A",C6="No",0) -> 0.5 | E6: Partial controls in place — gap remediation plan or timeline requested.
A7: 2 | B7: Is there a dedicated security leadership role (CISO or equivalent)? | C7: No | D7: =_xlfn.IFS(C7="Yes",1,C7="Partial",0.5,C7="N/A","N/A",C7="No",0) -> 0 | E7: Control not in place — vendor must provide remediation timeline.
A8: 3 | B8: Does the vendor conduct annual security risk assessments? | C8: Partial | D8: =_xlfn.IFS(C8="Yes",1,C8="Partial",0.5,C8="N/A","N/A",C8="No",0) -> 0.5 | E8: Partial controls in place — gap remediation plan or timeline requested.
A9: 4 | B9: Are security roles and responsibilities formally documented and communicated to staff? | C9: No | D9: =_xlfn.IFS(C9="Yes",1,C9="Partial",0.5,C9="N/A","N/A",C9="No",0) -> 0 | E9: Control not in place — vendor must provide remediation timeline.
A10: 5 | B10: Does the vendor maintain a security awareness training program for all employees? | C10: Partial | D10: =_xlfn.IFS(C10="Yes",1,C10="Partial",0.5,C10="N/A","N/A",C10="No",0) -> 0.5 | E10: Partial controls in place — gap remediation plan or timeline requested.
A11: 6 | B11: Does the vendor have a formal third-party / supply chain risk management program? | C11: No | D11: =_xlfn.IFS(C11="Yes",1,C11="Partial",0.5,C11="N/A","N/A",C11="No",0) -> 0 | E11: Control not in place — vendor must provide remediation timeline.
A12: 7 | B12: Are security metrics reported regularly to executive leadership or a board? | C12: No | D12: =_xlfn.IFS(C12="Yes",1,C12="Partial",0.5,C12="N/A","N/A",C12="No",0) -> 0 | E12: Control not in place — vendor must provide remediation timeline.
A13: 8 | B13: Does the vendor perform background checks on employees with access to client data? | C13: Yes | D13: =_xlfn.IFS(C13="Yes",1,C13="Partial",0.5,C13="N/A","N/A",C13="No",0) -> 1 | E13: Documentation / certification on file or available upon request.
A14: 9 | B14: Does the vendor have a documented acceptable use policy for systems and data? | C14: Partial | D14: =_xlfn.IFS(C14="Yes",1,C14="Partial",0.5,C14="N/A","N/A",C14="No",0) -> 0.5 | E14: Partial controls in place — gap remediation plan or timeline requested.
B15: Domain 1 Score — Organizational Security Governance | D15: =IFERROR(AVERAGEIF(D6:D14,"<>N/A",D6:D14),0) -> 0.33333333
A17: Domain 2: Data Security & Classification
A18: 10 | B18: Does the vendor maintain a data classification policy (e.g., Public, Confidential, Restricted)? | C18: Partial | D18: =_xlfn.IFS(C18="Yes",1,C18="Partial",0.5,C18="N/A","N/A",C18="No",0) -> 0.5 | E18: Partial controls in place — gap remediation plan or timeline requested.
A19: 11 | B19: Is data at rest encrypted using industry-standard algorithms (AES-256 or equivalent)? | C19: Yes | D19: =_xlfn.IFS(C19="Yes",1,C19="Partial",0.5,C19="N/A","N/A",C19="No",0) -> 1 | E19: Documentation / certification on file or available upon request.
A20: 12 | B20: Is data in transit encrypted using TLS 1.2 or higher? | C20: Yes | D20: =_xlfn.IFS(C20="Yes",1,C20="Partial",0.5,C20="N/A","N/A",C20="No",0) -> 1 | E20: Documentation / certification on file or available upon request.
A21: 13 | B21: Does the vendor maintain a data inventory identifying where client data is stored and processed? | C21: No | D21: =_xlfn.IFS(C21="Yes",1,C21="Partial",0.5,C21="N/A","N/A",C21="No",0) -> 0 | E21: Control not in place — vendor must provide remediation timeline.
A22: 14 | B22: Are data retention and destruction policies documented and enforced? | C22: Partial | D22: =_xlfn.IFS(C22="Yes",1,C22="Partial",0.5,C22="N/A","N/A",C22="No",0) -> 0.5 | E22: Partial controls in place — gap remediation plan or timeline requested.
A23: 15 | B23: Does the vendor restrict data processing to agreed geographic regions / jurisdictions? | C23: No | D23: =_xlfn.IFS(C23="Yes",1,C23="Partial",0.5,C23="N/A","N/A",C23="No",0) -> 0 | E23: Control not in place — vendor must provide remediation timeline.
A24: 16 | B24: Are encryption keys managed via a formal key management process (rotation, revocation)? | C24: No | D24: =_xlfn.IFS(C24="Yes",1,C24="Partial",0.5,C24="N/A","N/A",C24="No",0) -> 0 | E24: Control not in place — vendor must provide remediation timeline.
A25: 17 | B25: Is client data logically separated from other customers' data (multi-tenant controls)? | C25: Partial | D25: =_xlfn.IFS(C25="Yes",1,C25="Partial",0.5,C25="N/A","N/A",C25="No",0) -> 0.5 | E25: Partial controls in place — gap remediation plan or timeline requested.
A26: 18 | B26: Does the vendor have controls preventing unauthorized copying or exfiltration of data? | C26: No | D26: =_xlfn.IFS(C26="Yes",1,C26="Partial",0.5,C26="N/A","N/A",C26="No",0) -> 0 | E26: Control not in place — vendor must provide remediation timeline.
B27: Domain 2 Score — Data Security & Classification | D27: =IFERROR(AVERAGEIF(D18:D26,"<>N/A",D18:D26),0) -> 0.38888889
A29: Domain 3: Access Control & Identity Management
A30: 19 | B30: Is multi-factor authentication (MFA) enforced for all access to systems handling client data? | C30: Partial | D30: =_xlfn.IFS(C30="Yes",1,C30="Partial",0.5,C30="N/A","N/A",C30="No",0) -> 0.5 | E30: Partial controls in place — gap remediation plan or timeline requested.
A31: 20 | B31: Is role-based access control (RBAC) implemented with least-privilege principles? | C31: Partial | D31: =_xlfn.IFS(C31="Yes",1,C31="Partial",0.5,C31="N/A","N/A",C31="No",0) -> 0.5 | E31: Partial controls in place — gap remediation plan or timeline requested.
A32: 21 | B32: Are privileged accounts (admin/root) managed separately with enhanced controls? | C32: No | D32: =_xlfn.IFS(C32="Yes",1,C32="Partial",0.5,C32="N/A","N/A",C32="No",0) -> 0 | E32: Control not in place — vendor must provide remediation timeline.
A33: 22 | B33: Are access rights reviewed and recertified at least quarterly? | C33: No | D33: =_xlfn.IFS(C33="Yes",1,C33="Partial",0.5,C33="N/A","N/A",C33="No",0) -> 0 | E33: Control not in place — vendor must provide remediation timeline.
A34: 23 | B34: Is access promptly revoked upon employee termination or role change? | C34: Partial | D34: =_xlfn.IFS(C34="Yes",1,C34="Partial",0.5,C34="N/A","N/A",C34="No",0) -> 0.5 | E34: Partial controls in place — gap remediation plan or timeline requested.
A35: 24 | B35: Are all remote access sessions secured via VPN or equivalent encrypted tunnel? | C35: Yes | D35: =_xlfn.IFS(C35="Yes",1,C35="Partial",0.5,C35="N/A","N/A",C35="No",0) -> 1 | E35: Documentation / certification on file or available upon request.
A36: 25 | B36: Is single sign-on (SSO) implemented with a centralized identity provider? | C36: No | D36: =_xlfn.IFS(C36="Yes",1,C36="Partial",0.5,C36="N/A","N/A",C36="No",0) -> 0 | E36: Control not in place — vendor must provide remediation timeline.
A37: 26 | B37: Are service accounts inventoried and subject to the same access controls as user accounts? | C37: No | D37: =_xlfn.IFS(C37="Yes",1,C37="Partial",0.5,C37="N/A","N/A",C37="No",0) -> 0 | E37: Control not in place — vendor must provide remediation timeline.
A38: 27 | B38: Does the vendor log and monitor all privileged account activity? | C38: No | D38: =_xlfn.IFS(C38="Yes",1,C38="Partial",0.5,C38="N/A","N/A",C38="No",0) -> 0 | E38: Control not in place — vendor must provide remediation timeline.
B39: Domain 3 Score — Access Control & Identity Management | D39: =IFERROR(AVERAGEIF(D30:D38,"<>N/A",D30:D38),0) -> 0.27777778
A41: Domain 4: Incident Response & Notification
A42: 28 | B42: Does the vendor have a documented and tested Incident Response Plan (IRP)? | C42: No | D42: =_xlfn.IFS(C42="Yes",1,C42="Partial",0.5,C42="N/A","N/A",C42="No",0) -> 0 | E42: Control not in place — vendor must provide remediation timeline.
A43: 29 | B43: Are incident response roles and responsibilities (RACI) formally defined? | C43: No | D43: =_xlfn.IFS(C43="Yes",1,C43="Partial",0.5,C43="N/A","N/A",C43="No",0) -> 0 | E43: Control not in place — vendor must provide remediation timeline.
A44: 30 | B44: Does the vendor conduct tabletop exercises or simulated incident drills at least annually? | C44: No | D44: =_xlfn.IFS(C44="Yes",1,C44="Partial",0.5,C44="N/A","N/A",C44="No",0) -> 0 | E44: Control not in place — vendor must provide remediation timeline.
...

Sheet HRIS - Payroll Vendo
A1: Vendor Risk Assessment — HRIS / Payroll Vendor
A2: Service: HR & Payroll Processing | Risk Tier: Tier 2 – High | Meridian Pay Solutions | Q1 2026
A4: # | B4: Question | C4: Response (Y/P/N/NA) | D4: Score | E4: Notes / Evidence Required
A5: Domain 1: Organizational Security Governance
A6: 1 | B6: Does the vendor have a documented Information Security Policy reviewed at least annually? | C6: Yes | D6: =_xlfn.IFS(C6="Yes",1,C6="Partial",0.5,C6="N/A","N/A",C6="No",0) -> 1 | E6: Documentation / certification on file or available upon request.
A7: 2 | B7: Is there a dedicated security leadership role (CISO or equivalent)? | C7: Partial | D7: =_xlfn.IFS(C7="Yes",1,C7="Partial",0.5,C7="N/A","N/A",C7="No",0) -> 0.5 | E7: Partial controls in place — gap remediation plan or timeline requested.
A8: 3 | B8: Does the vendor conduct annual security risk assessments? | C8: Yes | D8: =_xlfn.IFS(C8="Yes",1,C8="Partial",0.5,C8="N/A","N/A",C8="No",0) -> 1 | E8: Documentation / certification on file or available upon request.
A9: 4 | B9: Are security roles and responsibilities formally documented and communicated to staff? | C9: Yes | D9: =_xlfn.IFS(C9="Yes",1,C9="Partial",0.5,C9="N/A","N/A",C9="No",0) -> 1 | E9: Documentation / certification on file or available upon request.
A10: 5 | B10: Does the vendor maintain a security awareness training program for all employees? | C10: Yes | D10: =_xlfn.IFS(C10="Yes",1,C10="Partial",0.5,C10="N/A","N/A",C10="No",0) -> 1 | E10: Documentation / certification on file or available upon request.
A11: 6 | B11: Does the vendor have a formal third-party / supply chain risk management program? | C11: Partial | D11: =_xlfn.IFS(C11="Yes",1,C11="Partial",0.5,C11="N/A","N/A",C11="No",0) -> 0.5 | E11: Partial controls in place — gap remediation plan or timeline requested.
A12: 7 | B12: Are security metrics reported regularly to executive leadership or a board? | C12: Partial | D12: =_xlfn.IFS(C12="Yes",1,C12="Partial",0.5,C12="N/A","N/A",C12="No",0) -> 0.5 | E12: Partial controls in place — gap remediation plan or timeline requested.
A13: 8 | B13: Does the vendor perform background checks on employees with access to client data? | C13: Yes | D13: =_xlfn.IFS(C13="Yes",1,C13="Partial",0.5,C13="N/A","N/A",C13="No",0) -> 1 | E13: Documentation / certification on file or available upon request.
A14: 9 | B14: Does the vendor have a documented acceptable use policy for systems and data? | C14: Yes | D14: =_xlfn.IFS(C14="Yes",1,C14="Partial",0.5,C14="N/A","N/A",C14="No",0) -> 1 | E14: Documentation / certification on file or available upon request.
B15: Domain 1 Score — Organizational Security Governance | D15: =IFERROR(AVERAGEIF(D6:D14,"<>N/A",D6:D14),0) -> 0.83333333
A17: Domain 2: Data Security & Classification
A18: 10 | B18: Does the vendor maintain a data classification policy (e.g., Public, Confidential, Restricted)? | C18: Yes | D18: =_xlfn.IFS(C18="Yes",1,C18="Partial",0.5,C18="N/A","N/A",C18="No",0) -> 1 | E18: Documentation / certification on file or available upon request.
A19: 11 | B19: Is data at rest encrypted using industry-standard algorithms (AES-256 or equivalent)? | C19: Yes | D19: =_xlfn.IFS(C19="Yes",1,C19="Partial",0.5,C19="N/A","N/A",C19="No",0) -> 1 | E19: Documentation / certification on file or available upon request.
A20: 12 | B20: Is data in transit encrypted using TLS 1.2 or higher? | C20: Yes | D20: =_xlfn.IFS(C20="Yes",1,C20="Partial",0.5,C20="N/A","N/A",C20="No",0) -> 1 | E20: Documentation / certification on file or available upon request.
A21: 13 | B21: Does the vendor maintain a data inventory identifying where client data is stored and processed? | C21: Partial | D21: =_xlfn.IFS(C21="Yes",1,C21="Partial",0.5,C21="N/A","N/A",C21="No",0) -> 0.5 | E21: Partial controls in place — gap remediation plan or timeline requested.
A22: 14 | B22: Are data retention and destruction policies documented and enforced? | C22: Yes | D22: =_xlfn.IFS(C22="Yes",1,C22="Partial",0.5,C22="N/A","N/A",C22="No",0) -> 1 | E22: Documentation / certification on file or available upon request.
A23: 15 | B23: Does the vendor restrict data processing to agreed geographic regions / jurisdictions? | C23: Yes | D23: =_xlfn.IFS(C23="Yes",1,C23="Partial",0.5,C23="N/A","N/A",C23="No",0) -> 1 | E23: Documentation / certification on file or available upon request.
A24: 16 | B24: Are encryption keys managed via a formal key management process (rotation, revocation)? | C24: Partial | D24: =_xlfn.IFS(C24="Yes",1,C24="Partial",0.5,C24="N/A","N/A",C24="No",0) -> 0.5 | E24: Partial controls in place — gap remediation plan or timeline requested.
A25: 17 | B25: Is client data logically separated from other customers' data (multi-tenant controls)? | C25: Yes | D25: =_xlfn.IFS(C25="Yes",1,C25="Partial",0.5,C25="N/A","N/A",C25="No",0) -> 1 | E25: Documentation / certification on file or available upon request.
A26: 18 | B26: Does the vendor have controls preventing unauthorized copying or exfiltration of data? | C26: Partial | D26: =_xlfn.IFS(C26="Yes",1,C26="Partial",0.5,C26="N/A","N/A",C26="No",0) -> 0.5 | E26: Partial controls in place — gap remediation plan or timeline requested.
B27: Domain 2 Score — Data Security & Classification | D27: =IFERROR(AVERAGEIF(D18:D26,"<>N/A",D18:D26),0) -> 0.83333333
A29: Domain 3: Access Control & Identity Management
A30: 19 | B30: Is multi-factor authentication (MFA) enforced for all access to systems handling client data? | C30: Yes | D30: =_xlfn.IFS(C30="Yes",1,C30="Partial",0.5,C30="N/A","N/A",C30="No",0) -> 1 | E30: Documentation / certification on file or available upon request.
A31: 20 | B31: Is role-based access control (RBAC) implemented with least-privilege principles? | C31: Yes | D31: =_xlfn.IFS(C31="Yes",1,C31="Partial",0.5,C31="N/A","N/A",C31="No",0) -> 1 | E31: Documentation / certification on file or available upon request.
A32: 21 | B32: Are privileged accounts (admin/root) managed separately with enhanced controls? | C32: Yes | D32: =_xlfn.IFS(C32="Yes",1,C32="Partial",0.5,C32="N/A","N/A",C32="No",0) -> 1 | E32: Documentation / certification on file or available upon request.
A33: 22 | B33: Are access rights reviewed and recertified at least quarterly? | C33: Partial | D33: =_xlfn.IFS(C33="Yes",1,C33="Partial",0.5,C33="N/A","N/A",C33="No",0) -> 0.5 | E33: Partial controls in place — gap remediation plan or timeline requested.
A34: 23 | B34: Is access promptly revoked upon employee termination or role change? | C34: Yes | D34: =_xlfn.IFS(C34="Yes",1,C34="Partial",0.5,C34="N/A","N/A",C34="No",0) -> 1 | E34: Documentation / certification on file or available upon request.
